Workbook

Sheet Hadith
A1: No. | B1: Topic | C1: Hadith (English) | D1: Narrator | E1: Arabic text | F1: Reference | G1: In-book reference | H1: Grade | I1: Link (sunnah.com)
A2: 1 | B2: Patience in trials & hardship | C2: The Prophet (ﷺ) said, "Soon others will be preferred to you, and there will be things which you will not like." The companions of the Prophet (ﷺ) asked, "O Allah's Messenger (ﷺ)! What do you order us to do (in this case)? " He said, "(I order you) to give the rights that are on you and to ask your rights from Allah" | D2: Narrated Ibn Mas`ud | E2: حَدَّثَنَا مُحَمَّدُ بْنُ كَثِيرٍ، أَخْبَرَنَا سُفْيَانُ، عَنِ الأَعْمَشِ، عَنْ زَيْدِ بْنِ وَهْبٍ، عَنِ ابْنِ مَسْعُودٍ، عَنِ النَّبِيِّ صلى الله عليه وسلم قَالَ ‏"‏ سَتَكُونُ أَثَرَةٌ وَأُمُورٌ تُنْكِرُونَهَا ‏"‏‏.‏ قَالُوا يَا رَسُولَ اللَّهِ فَمَا تَأْمُرُنَا قَالَ ‏"‏ تُؤَدُّونَ الْحَقَّ الَّذِي عَلَيْكُمْ، وَتَسْأَلُونَ اللَّهَ الَّذِي لَكُمْ ‏"‏‏.‏ | F2: Sahih al-Bukhari 3603 | G2: Book 61, Hadith 110 | H2: Sahih | I2: https://sunnah.com/bukhari:3603
A3: 2 | B3: Patience in trials & hardship | C3: The Prophet (ﷺ) passed by a woman who was weeping beside a grave. He told her to fear Allah and be patient. She said to him, "Go away, for you have not been afflicted with a calamity like mine." And she did not recognize him. Then she was informed that he was the Prophet (ﷺ) . so she went to the house of the Prophet (ﷺ) and there she did not find any guard. Then she said to him, "I did not recognize you." He said, "Verily, the patience is at the first stroke of a calamity" | D3: Narrated Anas bin Malik | E3: حَدَّثَنَا آدَمُ، حَدَّثَنَا شُعْبَةُ، حَدَّثَنَا ثَابِتٌ، عَنْ أَنَسِ بْنِ مَالِكٍ ـ رضى الله عنه ـ قَالَ مَرَّ النَّبِيُّ صلى الله عليه وسلم بِامْرَأَةٍ تَبْكِي عِنْدَ قَبْرٍ فَقَالَ ‏"‏ اتَّقِي اللَّهَ وَاصْبِرِي ‏"‏‏.‏ قَالَتْ إِلَيْكَ عَنِّي، فَإِنَّكَ لَمْ تُصَبْ بِمُصِيبَتِي، وَلَمْ تَعْرِفْهُ‏.‏ فَقِيلَ لَهَا إِنَّهُ النَّبِيُّ صلى الله عليه وسلم‏.‏ فَأَتَتْ باب النَّبِيِّ صلى الله عليه وسلم فَلَمْ تَجِدْ عِنْدَهُ بَوَّابِينَ فَقَالَتْ لَمْ أَعْرِفْكَ‏.‏ فَقَالَ ‏"‏ إِنَّمَا الصَّبْرُ عِنْدَ الصَّدْمَةِ الأُولَى ‏"‏‏.‏ | F3: Sahih al-Bukhari 1283 | G3: Book 23, Hadith 43 | H3: Sahih | I3: https://sunnah.com/bukhari:1283
A4: 3 | B4: Patience in trials & hardship | C4: Allah's Messenger (ﷺ) said, "If Allah wants to do good to somebody, He afflicts him with trials" | D4: Narrated Abu Huraira | E4: حَدَّثَنَا عَبْدُ اللَّهِ بْنُ يُوسُفَ، أَخْبَرَنَا مَالِكٌ، عَنْ مُحَمَّدِ بْنِ عَبْدِ اللَّهِ بْنِ عَبْدِ الرَّحْمَنِ بْنِ أَبِي صَعْصَعَةَ، أَنَّهُ قَالَ سَمِعْتُ سَعِيدَ بْنَ يَسَارٍ أَبَا الْحُبَابِ، يَقُولُ سَمِعْتُ أَبَا هُرَيْرَةَ، يَقُولُ قَالَ رَسُولُ اللَّهِ صلى الله عليه وسلم ‏ "‏ مَنْ يُرِدِ اللَّهُ بِهِ خَيْرًا يُصِبْ مِنْهُ ‏"‏‏.‏ | F4: Sahih al-Bukhari 5645 | G4: Book 75, Hadith 5 | H4: Sahih | I4: https://sunnah.com/bukhari:5645
A5: 4 | B5: Patience in trials & hardship | C5: The Prophet (ﷺ) said, "None of you should wish for death because of a calamity befalling him; but if he has to wish for death, he should say: "O Allah! Keep me alive as long as life is better for me, and let me die if death is better for me. | D5: Narrated Anas bin Malik | E5: حَدَّثَنَا آدَمُ، حَدَّثَنَا شُعْبَةُ، حَدَّثَنَا ثَابِتٌ الْبُنَانِيُّ، عَنْ أَنَسِ بْنِ مَالِكٍ ـ رضى الله عنه ـ قَالَ النَّبِيُّ صلى الله عليه وسلم ‏ "‏ لاَ يَتَمَنَّيَنَّ أَحَدُكُمُ الْمَوْتَ مِنْ ضُرٍّ أَصَابَهُ، فَإِنْ كَانَ لاَ بُدَّ فَاعِلاً فَلْيَقُلِ اللَّهُمَّ أَحْيِنِي مَا كَانَتِ الْحَيَاةُ خَيْرًا لِي، وَتَوَفَّنِي إِذَا كَانَتِ الْوَفَاةُ خَيْرًا لِي ‏"‏‏.‏ | F5: Sahih al-Bukhari 5671 | G5: Book 75, Hadith 31 | H5: Sahih | I5: https://sunnah.com/bukhari:5671
A6: 5 | B6: Patience in trials & hardship | C6: Some Ansari persons asked for (something) from Allah's Messenger (ﷺ) and he gave them. They again asked him for (something) and he again gave them. And then they asked him and he gave them again till all that was with him finished. And then he said "If I had anything. I would not keep it away from you. (Remember) Whoever abstains from asking others, Allah will make him contented, and whoever tries to make himself self-sufficient, Allah will make him self-sufficient. And whoever remains patient, Allah will make him patient. Nobody can be given a blessing better and greater than patience" | D6: Narrated Abu Sa`id Al-Khudri | E6: حَدَّثَنَا عَبْدُ اللَّهِ بْنُ يُوسُفَ، أَخْبَرَنَا مَالِكٌ، عَنِ ابْنِ شِهَابٍ، عَنْ عَطَاءِ بْنِ يَزِيدَ اللَّيْثِيِّ، عَنْ أَبِي سَعِيدٍ الْخُدْرِيِّ ـ رضى الله عنه ـ أَنَّ نَاسًا مِنَ الأَنْصَارِ سَأَلُوا رَسُولَ اللَّهِ صلى الله عليه وسلم فَأَعْطَاهُمْ، ثُمَّ سَأَلُوهُ فَأَعْطَاهُمْ، حَتَّى نَفِدَ مَا عِنْدَهُ فَقَالَ ‏ "‏ مَا يَكُونُ عِنْدِي مِنْ خَيْرٍ فَلَنْ أَدَّخِرَهُ عَنْكُمْ، وَمَنْ يَسْتَعْفِفْ يُعِفَّهُ اللَّهُ، وَمَنْ يَسْتَغْنِ يُغْنِهِ اللَّهُ، وَمَنْ يَتَصَبَّرْ يُصَبِّرْهُ اللَّهُ، وَمَا أُعْطِيَ أَحَدٌ عَطَاءً خَيْرًا وَأَوْسَعَ مِنَ الصَّبْرِ ‏"‏‏.‏ | F6: Sahih al-Bukhari 1469 | G6: Book 24, Hadith 71 | H6: Sahih | I6: https://sunnah.com/bukhari:1469
A7: 6 | B7: Patience in trials & hardship | C7: Allah's Messenger (ﷺ) said, "The example of a believer is that of a fresh tender plant; from whatever direction the wind comes, it bends it, but when the wind becomes quiet, it becomes straight again. Similarly, a believer is afflicted with calamities (but he remains patient till Allah removes his difficulties.) And an impious wicked person is like a pine tree which keeps hard and straight till Allah cuts (breaks) it down when He wishes." (See Hadith No. 558, Vol) | D7: Narrated Abu Huraira | E7: حَدَّثَنَا إِبْرَاهِيمُ بْنُ الْمُنْذِرِ، قَالَ حَدَّثَنِي مُحَمَّدُ بْنُ فُلَيْحٍ، قَالَ حَدَّثَنِي أَبِي، عَنْ هِلاَلِ بْنِ عَلِيٍّ، مِنْ بَنِي عَامِرِ بْنِ لُؤَىٍّ عَنْ عَطَاءِ بْنِ يَسَارٍ، عَنْ أَبِي هُرَيْرَةَ ـ رضى الله عنه ـ قَالَ قَالَ رَسُولُ اللَّهِ صلى الله عليه وسلم ‏ "‏ مَثَلُ الْمُؤْمِنِ كَمَثَلِ الْخَامَةِ مِنَ الزَّرْعِ مِنْ حَيْثُ أَتَتْهَا الرِّيحُ كَفَأَتْهَا، فَإِذَا اعْتَدَلَتْ تَكَفَّأُ بِالْبَلاَءِ، وَالْفَاجِرُ كَالأَرْزَةِ صَمَّاءَ مُعْتَدِلَةً حَتَّى يَقْصِمَهَا اللَّهُ إِذَا شَاءَ ‏"‏‏.‏ | F7: Sahih al-Bukhari 5644 | G7: Book 75, Hadith 4 | H7: Sahih | I7: https://sunnah.com/bukhari:5644
A8: 7 | B8: Patience in trials & hardship | C8: Once the Prophet (ﷺ) distributed something (among his followers. A man said, "This distribution has not been done (with justice) seeking Allah's Countenance." I went to the Prophet (ﷺ) and told him (of that). He became so angry that I saw the signs of anger on his face. Then he said, "May Allah bestow His Mercy on Moses, for he was harmed more (in a worse manner) than this; yet he endured patiently" | D8: Narrated `Abdullah | E8: حَدَّثَنَا أَبُو الْوَلِيدِ، حَدَّثَنَا شُعْبَةُ، عَنِ الأَعْمَشِ، قَالَ سَمِعْتُ أَبَا وَائِلٍ، قَالَ سَمِعْتُ عَبْدَ اللَّهِ ـ رضى الله عنه ـ قَالَ قَسَمَ النَّبِيُّ صلى الله عليه وسلم قَسْمًا، فَقَالَ رَجُلٌ إِنَّ هَذِهِ لَقِسْمَةٌ مَا أُرِيدَ بِهَا وَجْهُ اللَّهِ‏.‏ فَأَتَيْتُ النَّبِيَّ صلى الله عليه وسلم فَأَخْبَرْتُهُ، فَغَضِبَ حَتَّى رَأَيْتُ الْغَضَبَ فِي وَجْهِهِ، ثُمَّ قَالَ ‏ "‏ يَرْحَمُ اللَّهُ مُوسَى قَدْ أُوذِيَ بِأَكْثَرَ مِنْ هَذَا فَصَبَرَ ‏"‏‏.‏ | F8: Sahih al-Bukhari 3405 | G8: Book 60, Hadith 78 | H8: Sahih | I8: https://sunnah.com/bukhari:3405
A9: 8 | B9: Patience in trials & hardship | C9: I heard Allah's Messenger (ﷺ) saying, "Allah said, 'If I deprive my slave of his two beloved things (i.e., his eyes) and he remains patient, I will let him enter Paradise in compensation for them" | D9: Narrated Anas bin Malik | E9: حَدَّثَنَا عَبْدُ اللَّهِ بْنُ يُوسُفَ، حَدَّثَنَا اللَّيْثُ، قَالَ حَدَّثَنِي ابْنُ الْهَادِ، عَنْ عَمْرٍو، مَوْلَى الْمُطَّلِبِ عَنْ أَنَسِ بْنِ مَالِكٍ ـ رضى الله عنه ـ قَالَ سَمِعْتُ النَّبِيَّ صلى الله عليه وسلم يَقُولُ ‏ "‏ إِنَّ اللَّهَ قَالَ إِذَا ابْتَلَيْتُ عَبْدِي بِحَبِيبَتَيْهِ فَصَبَرَ عَوَّضْتُهُ مِنْهُمَا الْجَنَّةَ ‏"‏‏.‏ يُرِيدُ عَيْنَيْهِ‏.‏ تَابَعَهُ أَشْعَثُ بْنُ جَابِرٍ وَأَبُو ظِلاَلٍ عَنْ أَنَسٍ عَنِ النَّبِيِّ صلى الله عليه وسلم‏.‏ | F9: Sahih al-Bukhari 5653 | G9: Book 75, Hadith 13 | H9: Sahih | I9: https://sunnah.com/bukhari:5653
A10: 9 | B10: Patience in trials & hardship | C10: Ibn `Abbas said to me, "Shall I show you a woman of the people of Paradise?" I said, "Yes." He said, "This black lady came to the Prophet (ﷺ) and said, 'I get attacks of epilepsy and my body becomes uncovered; please invoke Allah for me.' The Prophet (ﷺ) said (to her), 'If you wish, be patient and you will have (enter) Paradise; and if you wish, I will invoke Allah to cure you.' She said, 'I will remain patient,' and added, 'but I become uncovered, so please invoke Allah for me that I may not become uncovered.' So he invoked Allah for her." Narrated 'Ata: That he had seen Um Zafar, the tall black lady, at (holding) the curtain of the Ka`ba. | D10: Narrated 'Ata bin Abi Rabah | E10: حَدَّثَنَا مُسَدَّدٌ، حَدَّثَنَا يَحْيَى، عَنْ عِمْرَانَ أَبِي بَكْرٍ، قَالَ حَدَّثَنِي عَطَاءُ بْنُ أَبِي رَبَاحٍ، قَالَ قَالَ لِي ابْنُ عَبَّاسٍ أَلاَ أُرِيكَ امْرَأَةً مِنْ أَهْلِ الْجَنَّةِ قُلْتُ بَلَى‏.‏ قَالَ هَذِهِ الْمَرْأَةُ السَّوْدَاءُ أَتَتِ النَّبِيَّ صلى الله عليه وسلم فَقَالَتْ إِنِّي أُصْرَعُ، وَإِنِّي أَتَكَشَّفُ فَادْعُ اللَّهَ لِي‏.‏ قَالَ ‏ "‏ إِنْ شِئْتِ صَبَرْتِ وَلَكِ الْجَنَّةُ وَإِنْ شِئْتِ دَعَوْتُ اللَّهَ أَنْ يُعَافِيَكِ ‏"‏‏.‏ فَقَالَتْ أَصْبِرُ‏.‏ فَقَالَتْ إِنِّي أَتَكَشَّفُ فَادْعُ اللَّهَ أَنْ لاَ أَتَكَشَّفَ، فَدَعَا لَهَا‏.‏ حَدَّثَنَا مُحَمَّدٌ، أَخْبَرَنَا مَخْلَدٌ، عَنِ ابْنِ جُرَيْجٍ، أَخْبَرَنِي عَطَاءٌ، أَنَّهُ رَأَى أُمَّ زُفَرَ تِلْكَ، امْرَأَةٌ طَوِيلَةٌ سَوْدَاءُ عَلَى سِتْرِ الْكَعْبَةِ‏.‏ | F10: Sahih al-Bukhari 5652 | G10: Book 75, Hadith 12 | H10: Sahih | I10: https://sunnah.com/bukhari:5652
A11: 10 | B11: Patience in trials & hardship | C11: Narrated Sa`d bin Ubaid:(the Maula of `Abdur-Rahman bin Azhar) Allah's Messenger (ﷺ) said, "None of you should long for death, for if he is a good man, he may increase his good deeds, and if he is an evil-doer, he may stop the evil deeds and repent" | E11: حَدَّثَنَا عَبْدُ اللَّهِ بْنُ مُحَمَّدٍ، حَدَّثَنَا هِشَامُ بْنُ يُوسُفَ، أَخْبَرَنَا مَعْمَرٌ، عَنِ الزُّهْرِيِّ، عَنْ أَبِي عُبَيْدٍ ـ اسْمُهُ سَعْدُ بْنُ عُبَيْدٍ مَوْلَى عَبْدِ الرَّحْمَنِ بْنِ أَزْهَرَ ـ عَنْ أَبِي هُرَيْرَةَ ـ أَنَّ رَسُولَ اللَّهِ صلى الله عليه وسلم قَالَ ‏ "‏ لاَ يَتَمَنَّى أَحَدُكُمُ الْمَوْتَ إِمَّا مُحْسِنًا فَلَعَلَّهُ يَزْدَادُ، وَإِمَّا مُسِيئًا فَلَعَلَّهُ يَسْتَعْتِبُ ‏"‏‏.‏ | F11: Sahih al-Bukhari 7235 | G11: Book 94, Hadith 10 | H11: Sahih | I11: https://sunnah.com/bukhari:7235
A12: 11 | B12: Patience in trials & hardship | C12: Allah's Messenger (ﷺ) said, "Allah gives respite to the oppressor, but when He takes him over, He never releases him." Then he recited:-- "Such is the seizure of your Lord when He seizes (population of) towns in the midst of their wrong: Painful indeed, and severe is His seizure" | D12: Narrated Abu Musa | E12: حَدَّثَنَا صَدَقَةُ بْنُ الْفَضْلِ، أَخْبَرَنَا أَبُو مُعَاوِيَةَ، حَدَّثَنَا بُرَيْدُ بْنُ أَبِي بُرْدَةَ، عَنْ أَبِي بُرْدَةَ، عَنْ أَبِي مُوسَى ـ رضى الله عنه ـ قَالَ قَالَ رَسُولُ اللَّهِ صلى الله عليه وسلم ‏ "‏ إِنَّ اللَّهَ لَيُمْلِي لِلظَّالِمِ حَتَّى إِذَا أَخَذَهُ لَمْ يُفْلِتْهُ ‏"‏‏.‏ قَالَ ثُمَّ قَرَأَ ‏{‏وَكَذَلِكَ أَخْذُ رَبِّكَ إِذَا أَخَذَ الْقُرَى وَهْىَ ظَالِمَةٌ إِنَّ أَخْذَهُ أَلِيمٌ شَدِيدٌ‏}‏ | F12: Sahih al-Bukhari 4686 | G12: Book 65, Hadith 208 | H12: Sahih | I12: https://sunnah.com/bukhari:4686
A13: 12 | B13: Patience in trials & hardship | C13: Strange are the ways of a believer for there is good in every affair of his and this is not the case with anyone else except in the case of a believer for if he has an occasion to feel delight, he thanks (God), thus there is a good for him in it, and if he gets into trouble and shows resignation (and endures it patiently), there is a good for him in it. | D13: Suhaib reported that Allah's Messenger (ﷺ) said | E13: حَدَّثَنَا هَدَّابُ بْنُ خَالِدٍ الأَزْدِيُّ، وَشَيْبَانُ بْنُ فَرُّوخَ، جَمِيعًا عَنْ سُلَيْمَانَ بْنِ الْمُغِيرَةِ، - وَاللَّفْظُ لِشَيْبَانَ - حَدَّثَنَا سُلَيْمَانُ، حَدَّثَنَا ثَابِتٌ، عَنْ عَبْدِ الرَّحْمَنِ بْنِ أَبِي لَيْلَى، عَنْ صُهَيْبٍ، قَالَ قَالَ رَسُولُ اللَّهِ صلى الله عليه وسلم ‏ "‏ عَجَبًا لأَمْرِ الْمُؤْمِنِ إِنَّ أَمْرَهُ كُلَّهُ خَيْرٌ وَلَيْسَ ذَاكَ لأَحَدٍ إِلاَّ لِلْمُؤْمِنِ إِنْ أَصَابَتْهُ سَرَّاءُ شَكَرَ فَكَانَ خَيْرًا لَهُ وَإِنْ أَصَابَتْهُ ضَرَّاءُ صَبَرَ فَكَانَ خَيْرًا لَهُ ‏"‏ ‏.‏ | F13: Sahih Muslim 2999 | G13: Book 55, Hadith 82 | H13: Sahih | I13: https://sunnah.com/muslim:2999
A14: 13 | B14: Patience in trials & hardship | C14: O Messenger of Allah(s.a.w)! Which of the people is tried most severely?" He said: "The Prophets, then those nearest to them, then those nearest to them. A man is tried according to his religion; if he is firm in his religion, then his trials are more severe, and if he is frail in his religion, then he is tried according to the strength of his religion. The servant shall continue to be tried until he is left walking upon the earth without any sins. | D14: Mus'ab bin Sa'd narrated from his father that a man said | E14: حَدَّثَنَا قُتَيْبَةُ، حَدَّثَنَا حَمَّادُ بْنُ زَيْدٍ، عَنْ عَاصِمِ بْنِ بَهْدَلَةَ، عَنْ مُصْعَبِ بْنِ سَعْدٍ، عَنْ أَبِيهِ، قَالَ قُلْتُ يَا رَسُولَ اللَّهِ أَىُّ النَّاسِ أَشَدُّ بَلاَءً قَالَ ‏ "‏ الأَنْبِيَاءُ ثُمَّ الأَمْثَلُ فَالأَمْثَلُ فَيُبْتَلَى الرَّجُلُ عَلَى حَسَبِ دِينِهِ فَإِنْ كَانَ دِينُهُ صُلْبًا اشْتَدَّ بَلاَؤُهُ وَإِنْ كَانَ فِي دِينِهِ رِقَّةٌ ابْتُلِيَ عَلَى حَسَبِ دِينِهِ فَمَا يَبْرَحُ الْبَلاَءُ بِالْعَبْدِ حَتَّى يَتْرُكَهُ يَمْشِي عَلَى الأَرْضِ مَا عَلَيْهِ خَطِيئَةٌ ‏"‏ ‏.‏ قَالَ أَبُو عِيسَى هَذَا حَدِيثٌ حَسَنٌ صَحِيحٌ ‏.‏ وَفِي الْبَابِ عَنْ أَبِي هُرَيْرَةَ وَأُخْتِ حُذَيْفَةَ بْنِ الْيَمَانِ ‏أَنَّ النَّبِيَّ صَلَّى اللَّهُ عَلَيْهِ وَسَلَّمَ سُئِلَ أَيُّ النَّاسِ أَشَدُّ بَلَاءً قَالَ الْأَنْبِيَاءُ ثُمَّ الْأَمْثَلُ فَالْأَمْثَلُ | F14: Jami' at-Tirmidhi 2398 | G14: Book 36, Hadith 96 | H14: Hasan Sahih (Al-Albani) | I14: https://sunnah.com/tirmidhi:2398
A15: 14 | B15: Patience in trials & hardship | C15: The Messenger of Allah sent Mu'adh [bin Jabal] to Yemen, and said: 'Beware of the supplication of the oppressed; for indeed there is no barrier between it and Allah. | D15: Ibn 'Abbas narrated | E15: حَدَّثَنَا أَبُو كُرَيْبٍ، حَدَّثَنَا وَكِيعٌ، عَنْ زَكَرِيَّا بْنِ إِسْحَاقَ، عَنْ يَحْيَى بْنِ عَبْدِ اللَّهِ بْنِ صَيْفِيٍّ، عَنْ أَبِي مَعْبَدٍ، عَنِ ابْنِ عَبَّاسٍ، أَنَّ رَسُولَ اللَّهِ صلى الله عليه وسلم بَعَثَ مُعَاذَ بْنَ جَبَلٍ إِلَى الْيَمَنِ فَقَالَ ‏ "‏ اتَّقِ دَعْوَةَ الْمَظْلُومِ فَإِنَّهَا لَيْسَ بَيْنَهَا وَبَيْنَ اللَّهِ حِجَابٌ ‏"‏ ‏.‏ قَالَ أَبُو عِيسَى وَفِي الْبَابِ عَنْ أَنَسٍ وَأَبِي هُرَيْرَةَ وَعَبْدِ اللَّهِ بْنِ عُمَرَ وَأَبِي سَعِيدٍ ‏.‏ وَهَذَا حَدِيثٌ حَسَنٌ صَحِيحٌ وَأَبُو مَعْبَدٍ اسْمُهُ نَافِذٌ ‏.‏ | F15: Jami' at-Tirmidhi 2014 | G15: Book 27, Hadith 120 | H15: Sahih (Al-Albani) | I15: https://sunnah.com/tirmidhi:2014
A16: 15 | B16: Patience in trials & hardship | C16: “The believer who mixes with people and bears their annoyance with patience will have a greater reward than the believer who does not mix with people and does not put up with their annoyance.” | D16: It was narrated from Ibn ‘Umar that the Messenger of Allah (ﷺ) said | E16: حَدَّثَنَا عَلِيُّ بْنُ مَيْمُونٍ الرَّقِّيُّ، حَدَّثَنَا عَبْدُ الْوَاحِدِ بْنُ صَالِحٍ، حَدَّثَنَا إِسْحَاقُ بْنُ يُوسُفَ، عَنِ الأَعْمَشِ، عَنْ يَحْيَى بْنِ وَثَّابٍ، عَنِ ابْنِ عُمَرَ، قَالَ قَالَ رَسُولُ اللَّهِ ـ صلى الله عليه وسلم ـ ‏ "‏ الْمُؤْمِنُ الَّذِي يُخَالِطُ النَّاسَ وَيَصْبِرُ عَلَى أَذَاهُمْ أَعْظَمُ أَجْرًا مِنَ الْمُؤْمِنِ الَّذِي لاَ يُخَالِطُ النَّاسَ وَلاَ يَصْبِرُ عَلَى أَذَاهُمْ ‏"‏ ‏.‏ | F16: Sunan Ibn Majah 4032 | G16: Book 36, Hadith 107 | H16: Sahih (Al-Albani) | I16: https://sunnah.com/ibnmajah:4032
A17: 16 | B17: Patience in trials & hardship | C17: We complained to the Messenger of Allah [SAW] when he was reclining on his rolled-up Burdah in the shade of the Ka'bah. We said: 'Will you not pray for victory for us, will you not pray to Allah for us? | D17: It was narrated that Khabbab bin Al-Aratt said | E17: أَخْبَرَنَا يَعْقُوبُ بْنُ إِبْرَاهِيمَ، وَمُحَمَّدُ بْنُ الْمُثَنَّى، عَنْ يَحْيَى، عَنْ إِسْمَاعِيلَ، قَالَ حَدَّثَنَا قَيْسٌ، عَنْ خَبَّابِ بْنِ الأَرَتِّ، قَالَ شَكَوْنَا إِلَى رَسُولِ اللَّهِ صلى الله عليه وسلم وَهُوَ مُتَوَسِّدٌ بُرْدَةً لَهُ فِي ظِلِّ الْكَعْبَةِ فَقُلْنَا أَلاَ تَسْتَنْصِرُ لَنَا أَلاَ تَدْعُو اللَّهَ لَنَا | F17: Sunan an-Nasa'i 5320 | G17: Book 48, Hadith 281 | H17: Sahih (Al-Albani) | I17: https://sunnah.com/nasai:5320
A18: 17 | B18: Illness & pain | C18: The Prophet (ﷺ) used to say to the patient, "In the Name of Allah The earth of our land and the saliva of some of us cure our patient" | D18: Narrated `Aisha | E18: حَدَّثَنَا عَلِيُّ بْنُ عَبْدِ اللَّهِ، حَدَّثَنَا سُفْيَانُ، قَالَ حَدَّثَنِي عَبْدُ رَبِّهِ بْنُ سَعِيدٍ، عَنْ عَمْرَةَ، عَنْ عَائِشَةَ ـ رضى الله عنها ـ أَنَّ النَّبِيَّ صلى الله عليه وسلم كَانَ يَقُولُ لِلْمَرِيضِ ‏ "‏ بِسْمِ اللَّهِ، تُرْبَةُ أَرْضِنَا‏.‏ بِرِيقَةِ بَعْضِنَا، يُشْفَى سَقِيمُنَا بِإِذْنِ رَبِّنَا ‏"‏‏.‏ | F18: Sahih al-Bukhari 5745 | G18: Book 76, Hadith 60 | H18: Sahih | I18: https://sunnah.com/bukhari:5745
A19: 18 | B19: Illness & pain | C19: Narrated `Aisha:(the wife of the Prophet) I asked Allah's Messenger (ﷺ) about the plague. He told me that it was a Punishment sent by Allah on whom He wished, and Allah made it a source of mercy for the believers, for if one in the time of an epidemic plague stays in his country patiently hoping for Allah's Reward and believing that nothing will befall him except what Allah has written for him, he will get the reward of a martyr. | E19: حَدَّثَنَا مُوسَى بْنُ إِسْمَاعِيلَ، حَدَّثَنَا دَاوُدُ بْنُ أَبِي الْفُرَاتِ، حَدَّثَنَا عَبْدُ اللَّهِ بْنُ بُرَيْدَةَ، عَنْ يَحْيَى بْنِ يَعْمَرَ، عَنْ عَائِشَةَ ـ رضى الله عنها ـ زَوْجِ النَّبِيِّ صلى الله عليه وسلم قَالَتْ سَأَلْتُ رَسُولَ اللَّهِ صلى الله عليه وسلم عَنِ الطَّاعُونِ، فَأَخْبَرَنِي ‏ "‏ أَنَّهُ عَذَابٌ يَبْعَثُهُ اللَّهُ عَلَى مَنْ يَشَاءُ، وَأَنَّ اللَّهَ جَعَلَهُ رَحْمَةً لِلْمُؤْمِنِينَ، لَيْسَ مِنْ أَحَدٍ يَقَعُ الطَّاعُونُ فَيَمْكُثُ فِي بَلَدِهِ صَابِرًا مُحْتَسِبًا، يَعْلَمُ أَنَّهُ لاَ يُصِيبُهُ إِلاَّ مَا كَتَبَ اللَّهُ لَهُ، إِلاَّ كَانَ لَهُ مِثْلُ أَجْرِ شَهِيدٍ ‏"‏‏.‏ | F19: Sahih al-Bukhari 3474 | G19: Book 60, Hadith 141 | H19: Sahih | I19: https://sunnah.com/bukhari:3474
A20: 19 | B20: Illness & pain | C20: I visited Allah's Messenger (ﷺ) while he was suffering from a high fever. I said, "O Allah's Messenger (ﷺ)! You have a high fever." He said, "Yes, I have as much fever as two men of you." I said, "Is it because you will have a double reward?" He said, "Yes, it is so. No Muslim is afflicted with any harm, even if it were the prick of a thorn, but that Allah expiates his sins because of that, as a tree sheds its leaves" | D20: Narrated `Abdullah | E20: حَدَّثَنَا عَبْدَانُ، عَنْ أَبِي حَمْزَةَ، عَنِ الأَعْمَشِ، عَنْ إِبْرَاهِيمَ التَّيْمِيِّ، عَنِ الْحَارِثِ بْنِ سُوَيْدٍ، عَنْ عَبْدِ اللَّهِ، قَالَ دَخَلْتُ عَلَى رَسُولِ اللَّهِ صلى الله عليه وسلم وَهْوَ يُوعَكُ فَقُلْتُ يَا رَسُولَ اللَّهِ إِنَّكَ تُوعَكُ وَعْكًا شَدِيدًا‏.‏ قَالَ ‏"‏ أَجَلْ إِنِّي أُوعَكُ كَمَا يُوعَكُ رَجُلاَنِ مِنْكُمْ ‏"‏‏.‏ قُلْتُ ذَلِكَ أَنَّ لَكَ أَجْرَيْنِ قَالَ ‏"‏ أَجَلْ ذَلِكَ كَذَلِكَ، مَا مِنْ مُسْلِمٍ يُصِيبُهُ أَذًى شَوْكَةٌ فَمَا فَوْقَهَا، إِلاَّ كَفَّرَ اللَّهُ بِهَا سَيِّئَاتِهِ، كَمَا تَحُطُّ الشَّجَرَةُ وَرَقَهَا ‏"‏‏.‏ | F20: Sahih al-Bukhari 5648 | G20: Book 75, Hadith 8 | H20: Sahih | I20: https://sunnah.com/bukhari:5648
A21: 20 | B21: Illness & pain | C21: The Prophet (ﷺ) said, "No fatigue, nor disease, nor sorrow, nor sadness, nor hurt, nor distress befalls a Muslim, even if it were the prick he receives from a thorn, but that Allah expiates some of his sins for that" | D21: Narrated Abu Sa`id Al-Khudri and Abu Huraira | E21: حَدَّثَنِي عَبْدُ اللَّهِ بْنُ مُحَمَّدٍ، حَدَّثَنَا عَبْدُ الْمَلِكِ بْنُ عَمْرٍو، حَدَّثَنَا زُهَيْرُ بْنُ مُحَمَّدٍ، عَنْ مُحَمَّدِ بْنِ عَمْرِو بْنِ حَلْحَلَةَ، عَنْ عَطَاءِ بْنِ يَسَارٍ، عَنْ أَبِي سَعِيدٍ الْخُدْرِيِّ، وَعَنْ أَبِي هُرَيْرَةَ، عَنِ النَّبِيِّ صلى الله عليه وسلم قَالَ ‏ "‏ مَا يُصِيبُ الْمُسْلِمَ مِنْ نَصَبٍ وَلاَ وَصَبٍ وَلاَ هَمٍّ وَلاَ حُزْنٍ وَلاَ أَذًى وَلاَ غَمٍّ حَتَّى الشَّوْكَةِ يُشَاكُهَا، إِلاَّ كَفَّرَ اللَّهُ بِهَا مِنْ خَطَايَاهُ ‏"‏‏.‏ | F21: Sahih al-Bukhari 5641 | H21: Sahih | I21: https://sunnah.com/bukhari:5641
A22: 21 | B22: Illness & pain | C22: Thabit and I went to Anas bin Malik. Thabit said, "O Abu Hamza! I am sick." On that Anas said, "Shall I treat you with the Ruqya of Allah's Messenger (ﷺ)?" Thabit said, "Yes," Anas recited, "O Allah! The Lord of the people, the Remover of trouble! (Please) cure (Heal) (this patient), for You are the Healer. None brings about healing but You; a healing that will leave behind no ailment" | D22: Narrated `Abdul `Aziz | E22: حَدَّثَنَا مُسَدَّدٌ، حَدَّثَنَا عَبْدُ الْوَارِثِ، عَنْ عَبْدِ الْعَزِيزِ، قَالَ دَخَلْتُ أَنَا وَثَابِتٌ، عَلَى أَنَسِ بْنِ مَالِكٍ فَقَالَ ثَابِتٌ يَا أَبَا حَمْزَةَ اشْتَكَيْتُ‏.‏ فَقَالَ أَنَسٌ أَلاَ أَرْقِيكَ بِرُقْيَةِ رَسُولِ اللَّهِ صلى الله عليه وسلم قَالَ بَلَى‏.‏ قَالَ ‏ "‏ اللَّهُمَّ رَبَّ النَّاسِ مُذْهِبَ الْبَاسِ اشْفِ أَنْتَ الشَّافِي لاَ شَافِيَ إِلاَّ أَنْتَ، شِفَاءً لاَ يُغَادِرُ سَقَمًا ‏"‏‏.‏ | F22: Sahih al-Bukhari 5742 | G22: Book 76, Hadith 57 | H22: Sahih | I22: https://sunnah.com/bukhari:5742
A23: 22 | B23: Illness & pain | C23: I visited the Prophet (ﷺ) during his illness and touched him while he was having a fever. I said to him, "You have a high fever; is it because you will get a double reward?" He said, "Yes. No Muslim is afflicted with any harm, but that his sins will be annulled as the leave of a tree fall down" | D23: Narrated `Abdullah | E23: حَدَّثَنَا قَبِيصَةُ، حَدَّثَنَا سُفْيَانُ، عَنِ الأَعْمَشِ، عَنْ إِبْرَاهِيمَ التَّيْمِيِّ، عَنِ الْحَارِثِ بْنِ سُوَيْدٍ، عَنْ عَبْدِ اللَّهِ ـ رضى الله عنه ـ قَالَ أَتَيْتُ النَّبِيَّ صلى الله عليه وسلم فِي مَرَضِهِ فَمَسِسْتُهُ وَهْوَ يُوعَكُ وَعْكًا شَدِيدًا فَقُلْتُ إِنَّكَ لَتُوعَكُ وَعْكًا شَدِيدًا، وَذَلِكَ أَنَّ لَكَ أَجْرَيْنِ‏.‏ قَالَ ‏ "‏ أَجَلْ، وَمَا مِنْ مُسْلِمٍ يُصِيبُهُ أَذًى إِلاَّ حَاتَّتْ عَنْهُ خَطَايَاهُ كَمَا تَحَاتُّ وَرَقُ الشَّجَرِ ‏"‏‏.‏ | F23: Sahih al-Bukhari 5661 | G23: Book 75, Hadith 21 | H23: Sahih | I23: https://sunnah.com/bukhari:5661
A24: 23 | B24: Illness & pain | C24: The Prophet (ﷺ) said, "There is no disease that Allah has created, except that He also has created its treatment" | D24: Narrated Abu Huraira | E24: حَدَّثَنَا مُحَمَّدُ بْنُ الْمُثَنَّى، حَدَّثَنَا أَبُو أَحْمَدَ الزُّبَيْرِيُّ، حَدَّثَنَا عُمَرُ بْنُ سَعِيدِ بْنِ أَبِي حُسَيْنٍ، قَالَ حَدَّثَنِي عَطَاءُ بْنُ أَبِي رَبَاحٍ، عَنْ أَبِي هُرَيْرَةَ ـ رضى الله عنه ـ عَنِ النَّبِيِّ صلى الله عليه وسلم قَالَ ‏ "‏ مَا أَنْزَلَ اللَّهُ دَاءً إِلاَّ أَنْزَلَ لَهُ شِفَاءً ‏"‏‏.‏ | F24: Sahih al-Bukhari 5678 | G24: Book 76, Hadith 1 | H24: Sahih | I24: https://sunnah.com/bukhari:5678
A25: 24 | B25: Illness & pain | C25: Whenever Allah's Messenger (ﷺ) paid a visit to a patient, or a patient was brought to him, he used to invoke Allah, saying, "Take away the disease, O the Lord of the people! Cure him as You are the One Who cures. There is no cure but Yours, a cure that leaves no disease" | D25: Narrated `Aisha | E25: حَدَّثَنَا مُوسَى بْنُ إِسْمَاعِيلَ، حَدَّثَنَا أَبُو عَوَانَةَ، عَنْ مَنْصُورٍ، عَنْ إِبْرَاهِيمَ، عَنْ مَسْرُوقٍ، عَنْ عَائِشَةَ ـ رضى الله عنها أَنَّ رَسُولَ اللَّهِ صلى الله عليه وسلم كَانَ إِذَا أَتَى مَرِيضًا ـ أَوْ أُتِيَ بِهِ ـ قَالَ ‏ "‏ أَذْهِبِ الْبَاسَ رَبَّ النَّاسِ، اشْفِ وَأَنْتَ الشَّافِي لاَ شِفَاءَ إِلاَّ شِفَاؤُكَ، شِفَاءً لاَ يُغَادِرُ سَقَمًا ‏"‏‏.‏ قَالَ عَمْرُو بْنُ أَبِي قَيْسٍ وَإِبْرَاهِيمُ بْنُ طَهْمَانَ عَنْ مَنْصُورٍ عَنْ إِبْرَاهِيمَ وَأَبِي الضُّحَى إِذَا أُتِيَ بِالْمَرِيضِ، وَقَالَ جَرِيرٌ عَنْ مَنْصُورٍ عَنْ أَبِي الضُّحَى وَحْدَهُ، وَقَالَ إِذَا أَتَى مَرِيضًا‏.‏ | F25: Sahih al-Bukhari 5675 | G25: Book 75, Hadith 35 | H25: Sahih | I25: https://sunnah.com/bukhari:5675
A26: 25 | B26: Illness & pain | C26: Whenever Allah's Messenger (ﷺ) became sick, he would recite Mu'awwidhat (Surat Al-Falaq and Surat An- Nas) and then blow his breath over his body. When he became seriously ill, I used to recite (these two Suras) and rub his hands over his body hoping for its blessings. | D26: Narrated `Aisha | E26: حَدَّثَنَا عَبْدُ اللَّهِ بْنُ يُوسُفَ، أَخْبَرَنَا مَالِكٌ، عَنِ ابْنِ شِهَابٍ، عَنْ عُرْوَةَ، عَنْ عَائِشَةَ، رضى الله عنها أَنَّ رَسُولَ اللَّهِ صلى الله عليه وسلم كَانَ إِذَا اشْتَكَى يَقْرَأُ عَلَى نَفْسِهِ بِالْمُعَوِّذَاتِ وَيَنْفُثُ، فَلَمَّا اشْتَدَّ وَجَعُهُ كُنْتُ أَقْرَأُ عَلَيْهِ وَأَمْسَحُ بِيَدِهِ رَجَاءَ بَرَكَتِهَا‏.‏ | F26: Sahih al-Bukhari 5016 | G26: Book 66, Hadith 38 | H26: Sahih | I26: https://sunnah.com/bukhari:5016
A27: 26 | B27: Illness & pain | C27: Allah's Messenger (ﷺ) entered upon a sick bedouin in whom he went to visit and said to him, "Don't worry, Tahur (i.e., your illness will be a means of cleansing of your sins), if Allah Will." The bedouin said, "Tahur! No, but it is a fever that is burning in the body of an old man and it will make him visit his grave." The Prophet (ﷺ) said, "Then it is so" | D27: Narrated Ibn `Abbas | E27: حَدَّثَنَا مُحَمَّدٌ، حَدَّثَنَا عَبْدُ الْوَهَّابِ الثَّقَفِيُّ، حَدَّثَنَا خَالِدٌ الْحَذَّاءُ، عَنْ عِكْرِمَةَ، عَنِ ابْنِ عَبَّاسٍ ـ رضى الله عنهما ـ أَنَّ رَسُولَ اللَّهِ صلى الله عليه وسلم دَخَلَ عَلَى أَعْرَابِيٍّ يَعُودُهُ فَقَالَ ‏"‏ لاَ بَأْسَ عَلَيْكَ طَهُورٌ، إِنْ شَاءَ اللَّهُ ‏"‏‏.‏ قَالَ قَالَ الأَعْرَابِيُّ طَهُورٌ، بَلْ هِيَ حُمَّى تَفُورُ عَلَى شَيْخٍ كَبِيرٍ، تُزِيرُهُ الْقُبُورَ‏.‏ قَالَ النَّبِيُّ صلى الله عليه وسلم ‏"‏ فَنَعَمْ إِذًا ‏"‏‏.‏ | F27: Sahih al-Bukhari 7470 | G27: Book 97, Hadith 96 | H27: Sahih | I27: https://sunnah.com/bukhari:7470
A28: 27 | B28: Illness & pain | C28: I heard Abu Burda who accompanied Yazid bin Abi Kabsha on a journey. Yazid used to observe fasting on journeys. Abu Burda said to him, "I heard Abu Musa several times saying that Allah's Apostle said, 'When a slave falls ill or travels, then he will get reward similar to that he gets for good deeds practiced at home when in good health" | D28: Narrated Ibrahim Abu Isma`il As-Saksaki | E28: حَدَّثَنَا مَطَرُ بْنُ الْفَضْلِ، حَدَّثَنَا يَزِيدُ بْنُ هَارُونَ، حَدَّثَنَا الْعَوَّامُ، حَدَّثَنَا إِبْرَاهِيمُ أَبُو إِسْمَاعِيلَ السَّكْسَكِيُّ، قَالَ سَمِعْتُ أَبَا بُرْدَةَ، وَاصْطَحَبَ، هُوَ وَيَزِيدُ بْنُ أَبِي كَبْشَةَ فِي سَفَرٍ، فَكَانَ يَزِيدُ يَصُومُ فِي السَّفَرِ فَقَالَ لَهُ أَبُو بُرْدَةَ سَمِعْتُ أَبَا مُوسَى مِرَارًا يَقُولُ قَالَ رَسُولُ اللَّهِ صلى الله عليه وسلم ‏ "‏ إِذَا مَرِضَ الْعَبْدُ أَوْ سَافَرَ، كُتِبَ لَهُ مِثْلُ مَا كَانَ يَعْمَلُ مُقِيمًا صَحِيحًا ‏"‏‏.‏ | F28: Sahih al-Bukhari 2996 | G28: Book 56, Hadith 205 | H28: Sahih | I28: https://sunnah.com/bukhari:2996
A29: 28 | B29: Illness & pain | C29: Verily, when a Muslim visits his brother in Islam he is supposed to remain in the fruit garden of Paradise until he returns. | D29: Thauban reported Allah's Apostle (ﷺ) as saying | E29: حَدَّثَنَا يَحْيَى بْنُ حَبِيبٍ الْحَارِثِيُّ، حَدَّثَنَا يَزِيدُ بْنُ زُرَيْعٍ، حَدَّثَنَا خَالِدٌ، عَنْ أَبِي قِلاَبَةَ، عَنْ أَبِي أَسْمَاءَ الرَّحَبِيِّ، عَنْ ثَوْبَانَ، عَنِ النَّبِيِّ صلى الله عليه وسلم قَالَ ‏ "‏ إِنَّ الْمُسْلِمَ إِذَا عَادَ أَخَاهُ الْمُسْلِمَ لَمْ يَزَلْ فِي خُرْفَةِ الْجَنَّةِ حَتَّى يَرْجِعَ ‏"‏ ‏.‏ | F29: Sahih Muslim 2568c | G29: Book 45, Hadith 51 | H29: Sahih | I29: https://sunnah.com/muslim:2568c
A30: 29 | B30: Illness & pain | C30: Jabir b. Abdullah reported that Allah's Messenger (ﷺ) visited Umm Sa'ib or Umm Musayyib and said:Umm Sa'ib or Umm Musayyib. why is it that you are shivering? She said:" It is fever and may it not be blessed by Allah, whereupon he (the Holy Prophet) said: Don't curse fever for it expiates the sin of the children of Adam just as furnace removes the alloy of iron" | E30: حَدَّثَنِي عُبَيْدُ اللَّهِ بْنُ عُمَرَ الْقَوَارِيرِيُّ، حَدَّثَنَا يَزِيدُ بْنُ زُرَيْعٍ، حَدَّثَنَا الْحَجَّاجُ الصَّوَّافُ، حَدَّثَنِي أَبُو الزُّبَيْرِ، حَدَّثَنَا جَابِرُ بْنُ عَبْدِ اللَّهِ، أَنَّ رَسُولَ اللَّهِ صلى الله عليه وسلم دَخَلَ عَلَى أُمِّ السَّائِبِ أَوْ أُمِّ الْمُسَيَّبِ فَقَالَ ‏"‏ مَا لَكِ يَا أُمَّ السَّائِبِ أَوْ يَا أُمَّ الْمُسَيَّبِ تُزَفْزِفِينَ ‏"‏ ‏.‏ قَالَتِ الْحُمَّى لاَ بَارَكَ اللَّهُ فِيهَا ‏.‏ فَقَالَ ‏"‏ لاَ تَسُبِّي الْحُمَّى فَإِنَّهَا تُذْهِبُ خَطَايَا بَنِي آدَمَ كَمَا يُذْهِبُ الْكِيرُ خَبَثَ الْحَدِيدِ ‏"‏ ‏.‏ | F30: Sahih Muslim 2575 | G30: Book 45, Hadith 68 | H30: Sahih | I30: https://sunnah.com/muslim:2575
A31: 30 | B31: Illness & pain | C31: Uthman b. Abu al-'As Al-Thaqafi reported that he made a complaint of pain to Allah's Messenger (ﷺ) that he felt in his body at the time he had become Muslim. Thereupon Allah's Messenger (ﷺ) said:Place your hand at the place where you feel pain in your body and say Bismillah (in the name of Allah) three times and seven times A'udhu billahi wa qudratihi min sharri ma ajidu wa uhadhiru (I seek refuge with Allah and with His Power from the evil that I find and that I fear) | E31: حَدَّثَنِي أَبُو الطَّاهِرِ، وَحَرْمَلَةُ بْنُ يَحْيَى، قَالاَ أَخْبَرَنَا ابْنُ وَهْبٍ، أَخْبَرَنِي يُونُسُ، عَنِ ابْنِ شِهَابٍ، أَخْبَرَنِي نَافِعُ بْنُ جُبَيْرِ بْنِ مُطْعِمٍ، عَنْ عُثْمَانَ بْنِ أَبِي الْعَاصِ الثَّقَفِيِّ، أَنَّهُ شَكَا إِلَى رَسُولِ اللَّهِ صلى الله عليه وسلم وَجَعًا يَجِدُهُ فِي جَسَدِهِ مُنْذُ أَسْلَمَ ‏.‏ فَقَالَ لَهُ رَسُولُ اللَّهِ صلى الله عليه وسلم ‏ "‏ ضَعْ يَدَكَ عَلَى الَّذِي تَأَلَّمَ مِنْ جَسَدِكَ وَقُلْ بِاسْمِ اللَّهِ ‏.‏ ثَلاَثًا ‏.‏ وَقُلْ سَبْعَ مَرَّاتٍ أَعُوذُ بِاللَّهِ وَقُدْرَتِهِ مِنْ شَرِّ مَا أَجِدُ وَأُحَاذِرُ ‏"‏ ‏.‏ | F31: Sahih Muslim 2202 | G31: Book 39, Hadith 91 | H31: Sahih | I31: https://sunnah.com/muslim:2202
A32: 31 | B32: Illness & pain | C32: I visited Allah's Messenger (ﷺ) as he was running a high temperature. I touched his body with my hand and said to him: Allah's Messenger, you are running a high temperature, whereupon Allah's Messenger (ﷺ) said: Yes, it is so. I comparatively have a more severe fever than any one of you. I said: Is it because there is a double reward in store for you? Thereupon Allah's Messenger (ﷺ) said: Yes, it is so. And Allah's Messenger (ﷺ) again said: When a Muslim falls ill, his compensation is that his minor sins are obliterated just as leaves fall (in autumn). In the hadith transmitted on the authority of Zubair there is (no mention of these words):" I touched his body with my hands" | D32: Abdullah reported | E32: حَدَّثَنَا عُثْمَانُ بْنُ أَبِي شَيْبَةَ، وَزُهَيْرُ بْنُ حَرْبٍ، وَإِسْحَاقُ بْنُ إِبْرَاهِيمَ، قَالَ إِسْحَاقُ أَخْبَرَنَا وَقَالَ الآخَرَانِ، حَدَّثَنَا جَرِيرٌ، عَنِ الأَعْمَشِ، عَنْ إِبْرَاهِيمَ التَّيْمِيِّ، عَنِ الْحَارِثِ بْنِ سُوَيْدٍ، عَنْ عَبْدِ اللَّهِ، قَالَ دَخَلْتُ عَلَى رَسُولِ اللَّهِ صلى الله عليه وسلم وَهُوَ يُوعَكُ فَمَسِسْتُهُ بِيَدِي فَقُلْتُ يَا رَسُولَ اللَّهِ إِنَّكَ لَتُوعَكُ وَعْكًا شَدِيدًا ‏.‏ فَقَالَ رَسُولُ اللَّهِ صلى الله عليه وسلم ‏"‏ أَجَلْ إِنِّي أُوعَكُ كَمَا يُوعَكُ رَجُلاَنِ مِنْكُمْ ‏"‏ ‏.‏ قَالَ فَقُلْتُ ذَلِكَ أَنَّ لَكَ أَجْرَيْنِ فَقَالَ رَسُولُ اللَّهِ صلى الله عليه وسلم ‏"‏ أَجَلْ ‏"‏ ‏.‏ ثُمَّ قَالَ رَسُولُ اللَّهِ صلى الله عليه وسلم ‏"‏ مَا مِنْ مُسْلِمٍ يُصِيبُهُ أَذًى مِنْ مَرَضٍ فَمَا سِوَاهُ إِلاَّ حَطَّ اللَّهُ بِهِ سَيِّئَاتِهِ كَمَا تَحُطُّ الشَّجَرَةُ وَرَقَهَا ‏"‏ ‏.‏ وَلَيْسَ فِي حَدِيثِ زُهَيْرٍ فَمَسِسْتُهُ بِيَدِي ‏.‏ | F32: Sahih Muslim 2571a | G32: Book 45, Hadith 57 | H32: Sahih | I32: https://sunnah.com/muslim:2571a
A33: 32 | B33: Illness & pain | C33: Muhammad, have you fallen ill? Thereupon he said: Yes. He (Gabriel) said: "In the name of Allah I exorcise you from everything and safeguard you from every evil that may harm you and from the eye of a jealous one. Allah would cure you and I invoke the name of Allah for you" | D33: Abu Sa'id reported that Gabriel came to Allah's Messenger (ﷺ) and said | E33: حَدَّثَنَا بِشْرُ بْنُ هِلاَلٍ الصَّوَّافُ، حَدَّثَنَا عَبْدُ الْوَارِثِ، حَدَّثَنَا عَبْدُ الْعَزِيزِ بْنُ صُهَيْبٍ، عَنْ أَبِي نَضْرَةَ، عَنْ أَبِي سَعِيدٍ، أَنَّ جِبْرِيلَ، أَتَى النَّبِيَّ صلى الله عليه وسلم فَقَالَ يَا مُحَمَّدُ اشْتَكَيْتَ فَقَالَ ‏ "‏ نَعَمْ ‏"‏ ‏.‏ قَالَ بِاسْمِ اللَّهِ أَرْقِيكَ مِنْ كُلِّ شَىْءٍ يُؤْذِيكَ مِنْ شَرِّ كُلِّ نَفْسٍ أَوْ عَيْنِ حَاسِدٍ اللَّهُ يَشْفِيكَ بِاسْمِ اللَّهِ أَرْقِيكَ ‏.‏ | F33: Sahih Muslim 2186 | G33: Book 39, Hadith 54 | H33: Sahih | I33: https://sunnah.com/muslim:2186
A34: 33 | B34: Illness & pain | C34: Nigella seed is a remedy for every disease except death. | D34: Abu Huraira reported that he heard Allah's Messenger (ﷺ) as saying | E34: حَدَّثَنَا مُحَمَّدُ بْنُ رُمْحِ بْنِ الْمُهَاجِرِ، أَخْبَرَنَا اللَّيْثُ، عَنْ عُقَيْلٍ، عَنِ ابْنِ شِهَابٍ، أَخْبَرَنِي أَبُو سَلَمَةَ بْنُ عَبْدِ الرَّحْمَنِ، وَسَعِيدُ بْنُ الْمُسَيَّبِ، أَنَّ أَبَا هُرَيْرَةَ، أَخْبَرَهُمَا أَنَّهُ، سَمِعَ رَسُولَ اللَّهِ صلى الله عليه وسلم يَقُولُ ‏ "‏ إِنَّ فِي الْحَبَّةِ السَّوْدَاءِ شِفَاءً مِنْ كُلِّ دَاءٍ إِلاَّ السَّامَ ‏"‏ ‏.‏ وَالسَّامُ الْمَوْتُ ‏.‏ وَالْحَبَّةُ السَّوْدَاءُ الشُّونِيزُ ‏.‏ | F34: Sahih Muslim 2215a | G34: Book 39, Hadith 118 | H34: Sahih | I34: https://sunnah.com/muslim:2215a
A35: 34 | B35: Grief, loss & death of loved ones | C35: A man said to the Prophet, "My mother died suddenly, and I think that if she could speak, she would have given in charity. May I give in charity on her behalf?" He said, "Yes! Give in charity on her behalf" | D35: Narrated `Aisha | E35: حَدَّثَنَا إِسْمَاعِيلُ، قَالَ حَدَّثَنِي مَالِكٌ، عَنْ هِشَامٍ، عَنْ أَبِيهِ، عَنْ عَائِشَةَ، رضى الله عنها أَنَّ رَجُلاً، قَالَ لِلنَّبِيِّ صلى الله عليه وسلم إِنَّ أُمِّي افْتُلِتَتْ نَفْسَهَا، وَأُرَاهَا لَوْ تَكَلَّمَتْ تَصَدَّقَتْ، أَفَأَتَصَدَّقُ عَنْهَا قَالَ ‏ "‏ نَعَمْ، تَصَدَّقْ عَنْهَا ‏"‏‏.‏ | F35: Sahih al-Bukhari 2760 | G35: Book 55, Hadith 23 | H35: Sahih | I35: https://sunnah.com/bukhari:2760
A36: 35 | B36: Grief, loss & death of loved ones | C36: Allah's Messenger (ﷺ) said, "Allah says, 'I have nothing to give but Paradise as a reward to my believer slave, who, if I cause his dear friend (or relative) to die, remains patient (and hopes for Allah's Reward)" | D36: Narrated Abu Huraira | E36: حَدَّثَنَا قُتَيْبَةُ، حَدَّثَنَا يَعْقُوبُ بْنُ عَبْدِ الرَّحْمَنِ، عَنْ عَمْرٍو، عَنْ سَعِيدٍ الْمَقْبُرِيِّ، عَنْ أَبِي هُرَيْرَةَ، أَنَّ رَسُولَ اللَّهِ صلى الله عليه وسلم قَالَ ‏ "‏ يَقُولُ اللَّهُ تَعَالَى مَا لِعَبْدِي الْمُؤْمِنِ عِنْدِي جَزَاءٌ، إِذَا قَبَضْتُ صَفِيَّهُ مِنْ أَهْلِ الدُّنْيَا، ثُمَّ احْتَسَبَهُ إِلاَّ الْجَنَّةُ ‏"‏‏.‏ | F36: Sahih al-Bukhari 6424 | G36: Book 81, Hadith 13 | H36: Sahih | I36: https://sunnah.com/bukhari:6424
A37: 36 | B37: Grief, loss & death of loved ones | C37: The Prophet (ﷺ) said, "He who slaps the cheeks, tears the clothes and follows the traditions of the Days of Ignorance is not from us" | D37: Narrated `Abdullah | E37: حَدَّثَنَا عُمَرُ بْنُ حَفْصٍ، حَدَّثَنَا أَبِي، حَدَّثَنَا الأَعْمَشُ، عَنْ عَبْدِ اللَّهِ بْنِ مُرَّةَ، عَنْ مَسْرُوقٍ، عَنْ عَبْدِ اللَّهِ ـ رضى الله عنه ـ قَالَ قَالَ النَّبِيُّ صلى الله عليه وسلم ‏ "‏ لَيْسَ مِنَّا مَنْ ضَرَبَ الْخُدُودَ، وَشَقَّ الْجُيُوبَ، وَدَعَا بِدَعْوَى الْجَاهِلِيَّةِ ‏"‏‏.‏ | F37: Sahih al-Bukhari 1298 | G37: Book 23, Hadith 56 | H37: Sahih | I37: https://sunnah.com/bukhari:1298
A38: 37 | B38: Grief, loss & death of loved ones | C38: The Prophet (ﷺ) said, "A Muslim whose three children die before the age of puberty will be granted Paradise by Allah due to his mercy for them" | D38: Narrated Anas | E38: حَدَّثَنَا أَبُو مَعْمَرٍ، حَدَّثَنَا عَبْدُ الْوَارِثِ، حَدَّثَنَا عَبْدُ الْعَزِيزِ، عَنْ أَنَسٍ ـ رضى الله عنه ـ قَالَ قَالَ النَّبِيُّ صلى الله عليه وسلم ‏ "‏ مَا مِنَ النَّاسِ مِنْ مُسْلِمٍ يُتَوَفَّى لَهُ ثَلاَثٌ لَمْ يَبْلُغُوا الْحِنْثَ، إِلاَّ أَدْخَلَهُ اللَّهُ الْجَنَّةَ بِفَضْلِ رَحْمَتِهِ إِيَّاهُمْ ‏"‏‏.‏ | F38: Sahih al-Bukhari 1248 | G38: Book 23, Hadith 11 | H38: Sahih | I38: https://sunnah.com/bukhari:1248
A39: 38 | B39: Grief, loss & death of loved ones | C39: We went with Allah's Messenger (ﷺ) to the blacksmith Abu Saif, and he was the husband of the wet-nurse of Ibrahim (the son of the Prophet). Allah's Messenger (ﷺ) took Ibrahim and kissed him and smelled him and later we entered Abu Saif's house and at that time Ibrahim was in his last breaths, and the eyes of Allah's Messenger (ﷺ) started shedding tears. `Abdur Rahman bin `Auf said, "O Allah's Apostle, even you are weeping!" He said, "O Ibn `Auf, this is mercy." Then he wept more and said, "The eyes are shedding tears and the heart is grieved, and we will not say except what pleases our Lord, O Ibrahim ! Indeed we are grieved by your separation" | D39: Narrated Anas bin Malik | E39: حَدَّثَنَا الْحَسَنُ بْنُ عَبْدِ الْعَزِيزِ، حَدَّثَنَا يَحْيَى بْنُ حَسَّانَ، حَدَّثَنَا قُرَيْشٌ ـ هُوَ ابْنُ حَيَّانَ ـ عَنْ ثَابِتٍ، عَنْ أَنَسِ بْنِ مَالِكٍ ـ رضى الله عنه ـ قَالَ دَخَلْنَا مَعَ رَسُولِ اللَّهِ صلى الله عليه وسلم عَلَى أَبِي سَيْفٍ الْقَيْنِ ـ وَكَانَ ظِئْرًا لإِبْرَاهِيمَ ـ عَلَيْهِ السَّلاَمُ ـ فَأَخَذَ رَسُولُ اللَّهِ صلى الله عليه وسلم إِبْرَاهِيمَ فَقَبَّلَهُ وَشَمَّهُ، ثُمَّ دَخَلْنَا عَلَيْهِ بَعْدَ ذَلِكَ، وَإِبْرَاهِيمُ يَجُودُ بِنَفْسِهِ، فَجَعَلَتْ عَيْنَا رَسُولِ اللَّهِ صلى الله عليه وسلم تَذْرِفَانِ‏.‏ فَقَالَ لَهُ عَبْدُ الرَّحْمَنِ بْنُ عَوْفٍ ـ رضى الله عنه ـ وَأَنْتَ يَا رَسُولَ اللَّهِ فَقَالَ ‏"‏ يَا ابْنَ عَوْفٍ إِنَّهَا رَحْمَةٌ ‏"‏‏.‏ ثُمَّ أَتْبَعَهَا بِأُخْرَى فَقَالَ صلى الله عليه وسلم ‏"‏ إِنَّ الْعَيْنَ تَدْمَعُ، وَالْقَلْبَ يَحْزَنُ، وَلاَ نَقُولُ إِلاَّ مَا يَرْضَى رَبُّنَا، وَإِنَّا بِفِرَاقِكَ يَا إِبْرَاهِيمُ لَمَحْزُونُونَ ‏"‏‏.‏ رَوَاهُ مُوسَى عَنْ سُلَيْمَانَ بْنِ الْمُغِيرَةِ عَنْ ثَابِتٍ عَنْ أَنَسٍ ـ رضى الله عنه ـ عَنِ النَّبِيِّ صلى الله عليه وسلم‏.‏ | F39: Sahih al-Bukhari 1303 | G39: Book 23, Hadith 61 | H39: Sahih | I39: https://sunnah.com/bukhari:1303
A40: 39 | B40: Grief, loss & death of loved ones | C40: When the ailment of the Prophet (ﷺ) got aggravated, he became unconscious whereupon Fatima said, "Oh, how distressed my father is!" He said, "Your father will have no more distress after today." When he expired, she said, "O Father! Who has responded to the call of the Lord Who has invited him! O Father, whose dwelling place is the Garden of Paradise (i.e. Al-Firdaus)! O Father! We convey this news (of your death) to Gabriel." When he was buried, Fatima said, "O Anas! Do you feel pleased to throw earth over Allah's Messenger (ﷺ)?" | D40: Narrated Anas | E40: حَدَّثَنَا سُلَيْمَانُ بْنُ حَرْبٍ، حَدَّثَنَا حَمَّادٌ، عَنْ ثَابِتٍ، عَنْ أَنَسٍ، قَالَ لَمَّا ثَقُلَ النَّبِيُّ صلى الله عليه وسلم جَعَلَ يَتَغَشَّاهُ، فَقَالَتْ فَاطِمَةُ ـ عَلَيْهَا السَّلاَمُ ـ وَاكَرْبَ أَبَاهُ‏.‏ فَقَالَ لَهَا ‏ "‏ لَيْسَ عَلَى أَبِيكِ كَرْبٌ بَعْدَ الْيَوْمِ ‏"‏‏.‏ فَلَمَّا مَاتَ قَالَتْ يَا أَبَتَاهْ، أَجَابَ رَبًّا دَعَاهُ، يَا أَبَتَاهْ مَنْ جَنَّةُ الْفِرْدَوْسِ مَأْوَاهُ، يَا أَبَتَاهْ إِلَى جِبْرِيلَ نَنْعَاهْ‏.‏ فَلَمَّا دُفِنَ قَالَتْ فَاطِمَةُ ـ عَلَيْهَا السَّلاَمُ ـ يَا أَنَسُ، أَطَابَتْ أَنْفُسُكُمْ أَنْ تَحْثُوا عَلَى رَسُولِ اللَّهِ صلى الله عليه وسلم التُّرَابَ | F40: Sahih al-Bukhari 4462 | G40: Book 64, Hadith 478 | H40: Sahih | I40: https://sunnah.com/bukhari:4462
...

Sheet Topics
A1: Topic | B1: Count
A2: Patience in trials & hardship | B2: =COUNTIF(Hadith!B:B,A2) -> 16
A3: Illness & pain | B3: =COUNTIF(Hadith!B:B,A3) -> 17
A4: Grief, loss & death of loved ones | B4: =COUNTIF(Hadith!B:B,A4) -> 16
A5: Worry, anxiety & distress | B5: =COUNTIF(Hadith!B:B,A5) -> 12
A6: Hope in Allah's mercy | B6: =COUNTIF(Hadith!B:B,A6) -> 24
A7: Repentance & forgiveness of sins | B7: =COUNTIF(Hadith!B:B,A7) -> 21
A8: Trust in Allah & destiny | B8: =COUNTIF(Hadith!B:B,A8) -> 11
A9: Duas for difficult times | B9: =COUNTIF(Hadith!B:B,A9) -> 34
A10: Remembrance of Allah & peace of heart | B10: =COUNTIF(Hadith!B:B,A10) -> 32
A11: Gratitude | B11: =COUNTIF(Hadith!B:B,A11) -> 15
A12: Provision, poverty & contentment | B12: =COUNTIF(Hadith!B:B,A12) -> 19
A13: Debt & financial worries | B13: =COUNTIF(Hadith!B:B,A13) -> 10
... A28: This world & the hereafter | B28: =COUNTIF(Hadith!B:B,A28) -> 17
A29: Total | B29: =SUM(B2:B28) -> 500
A31: By collection | B31: Count
A32: Sahih al-Bukhari | B32: =COUNTIF(Hadith!F:F,"Sahih al-Bukhari *") -> 219
A33: Sahih Muslim | B33: =COUNTIF(Hadith!F:F,"Sahih Muslim *") -> 107
A34: Jami' at-Tirmidhi | B34: =COUNTIF(Hadith!F:F,"Jami' at-Tirmidhi *") -> 82
A35: Sunan Ibn Majah | B35: =COUNTIF(Hadith!F:F,"Sunan Ibn Majah *") -> 42
A36: Sunan an-Nasa'i | B36: =COUNTIF(Hadith!F:F,"Sunan an-Nasa'i *") -> 6
A37: Sunan Abi Dawud | B37: =COUNTIF(Hadith!F:F,"Sunan Abi Dawud *") -> 44

Sheet About
A1: 500 hadith on daily-life issues and consolation, grouped into 27 topics.
A2: Sources: Sahih al-Bukhari and Sahih Muslim (all), plus Jami' at-Tirmidhi, Sunan Abi Dawud, Sunan Ibn Majah and Sunan an-Nasa'i — only narrations Shaykh al-Albani graded Sahih or Hasan, with no other listed grader calling them weak; Companion statements (mawquf) excluded.
A3: Reference numbers follow sunnah.com (Muslim uses the Fu'ad 'Abd al-Baqi numbering, e.g. 2999, with a/b letters for variants). The Link column opens each hadith.
A4: English translations are the standard sunnah.com translations, taken from the open hadith-api dataset (github.com/fawazahmed0/hadith-api). Arabic text includes the full chain of narrators.
A5: Riyad as-Salihin (Imam an-Nawawi) was used to prioritise narrations scholars already collected for everyday conduct.
A6: Topic labels are an editorial grouping for browsing; some hadith fit several topics.
A7: Before publishing in an app, have a qualified scholar review the selection and topic assignments.
